<?xml version="1.0" encoding="UTF-8"?>
<robot xmlns:xacro="http://www.ros.org/wiki/xacro" name="robot5">

    <xacro:include filename="$(find rover_desc)/urdf/inertial_macros.xacro"/>
    
    <xacro:property name="robot_namespace" value="robot5" />

    <gazebo>
        <plugin name="gazebo_control" filename="libgazebo_ros_diff_drive.so">

            <num_wheel_pairs>2</num_wheel_pairs>
            
            <ros>
                <namespace>${robot_namespace}</namespace>
            </ros>

            <left_joint>lb_wheel_joint</left_joint>
            <right_joint>rb_wheel_joint</right_joint>

            <left_joint>lf_wheel_joint</left_joint>
            <right_joint>rf_wheel_joint</right_joint>

            <wheel_separation>1.2</wheel_separation>
            <wheel_diameter>0.45</wheel_diameter>

            <command_topic>cmd_vel</command_topic>
            <update_rate>50</update_rate>       

            <max_wheel_torque>100</max_wheel_torque>
            <max_wheel_acceleration>5.0</max_wheel_acceleration>
            
            <odometry_frame>odom</odometry_frame>
            <robot_base_frame>base_link</robot_base_frame>
        
            <publish_odom>true</publish_odom>
            <publish_odom_tf>true</publish_odom_tf>
            <publish_wheel_tf>true</publish_wheel_tf>

        </plugin>
    </gazebo>
<!-- 
    <gazebo reference="lb_wheel">
        <mu1>1.8</mu1>
        <mu2>1.8</mu2>
    </gazebo>

    <gazebo reference="lf_wheel">
        <mu1>1.8</mu1>
        <mu2>1.8</mu2>
    </gazebo>

    <gazebo reference="rb_wheel">
        <mu1>1.8</mu1>
        <mu2>1.8</mu2>
    </gazebo>

    <gazebo reference="rf_wheel">
        <mu1>1.8</mu1>
        <mu2>1.8</mu2>
    </gazebo> -->

    <material name="white">
        <color rgba="1 1 1 1" />
    </material>

    <material name="orange">
        <color rgba="1 0.3 0.1 1"/>
    </material>

    <material name="blue">
        <color rgba="0.2 0.2 1 1"/>
    </material>

    <material name="black">
        <color rgba="0 0 0 1"/>
    </material>

    <link name="base_link">
        <visual>
            <origin xyz="0 0 0"/>
            <geometry>
                <box size="1.8 1.2 1.2"/>
            </geometry>
            <material name="white"/>
        </visual>
        <collision>
            <origin xyz="0 0 0"/>
            <geometry>
                <box size="1.8 1.2 1.2"/>
            </geometry>
        </collision>
        <xacro:inertial_box mass="5.0" x="1.8" y="1.2" z="1.2">
            <origin xyz="0 0 0" rpy="0 0 0"/>
        </xacro:inertial_box>
    </link>

    <link name="lf_wheel">
        <visual>
            <origin xyz="0 0 0"/>
            <geometry>
                <cylinder radius="0.225" length="0.22"/>
            </geometry>            
        </visual>
        <collision>
            <origin xyz="0 0 0"/>
            <geometry>
                <cylinder radius="0.225" length="0.22"/>
            </geometry>
        </collision>
        <xacro:inertial_cylinder mass="0.25" length="0.22" radius="0.225">
            <origin xyz="0 0 0" rpy="0 0 0"/>
        </xacro:inertial_cylinder>
    </link>

    <joint name="lf_wheel_joint" type="continuous">
        <parent link="base_link" />
        <child link="lf_wheel" />
        <origin xyz="0.45 0.6 -0.6" rpy="-${pi/2} 0 0"/>
        <axis xyz="0 0 1"/>
    </joint>

    <link name="rf_wheel">
        <visual>
            <origin xyz="0 0 0"/>
            <geometry>
                <cylinder radius="0.225" length="0.22"/>
            </geometry>            
        </visual>
        <collision>
            <origin xyz="0 0 0"/>
            <geometry>
                <cylinder radius="0.225" length="0.22"/>
            </geometry>
        </collision>
        <xacro:inertial_cylinder mass="0.25" length="0.22" radius="0.225">
            <origin xyz="0 0 0" rpy="0 0 0"/>
        </xacro:inertial_cylinder>
    </link>

    <joint name="rf_wheel_joint" type="continuous">
        <parent link="base_link" />
        <child link="rf_wheel" />
        <origin xyz="0.45 -0.6 -0.6" rpy="${pi/2} 0 0"/>
        <axis xyz="0 0 -1"/>
    </joint>

    <link name="lb_wheel">
        <visual>
            <origin xyz="0 0 0"/>
            <geometry>
                <cylinder radius="0.225" length="0.22"/>
            </geometry>            
        </visual>
        <collision>
            <origin xyz="0 0 0"/>
            <geometry>
                <cylinder radius="0.225" length="0.22"/>
            </geometry>
        </collision>
        <xacro:inertial_cylinder mass="0.25" length="0.22" radius="0.225">
            <origin xyz="0 0 0" rpy="0 0 0"/>
        </xacro:inertial_cylinder>
    </link>

    <joint name="lb_wheel_joint" type="continuous">
        <parent link="base_link" />
        <child link="lb_wheel" />
        <origin xyz="-0.45 0.6 -0.6" rpy="-${pi/2} 0 0"/>
        <axis xyz="0 0 1"/>
    </joint>

    <link name="rb_wheel">
        <visual>
            <origin xyz="0 0 0"/>
            <geometry>
                <cylinder radius="0.225" length="0.22"/>
            </geometry>            
        </visual>
        <collision>
            <origin xyz="0 0 0"/>
            <geometry>
                <cylinder radius="0.225" length="0.22"/>
            </geometry>
        </collision>
        <xacro:inertial_cylinder mass="0.25" length="0.22" radius="0.225">
            <origin xyz="0 0 0" rpy="0 0 0"/>
        </xacro:inertial_cylinder>
    </link>

    <joint name="rb_wheel_joint" type="continuous">
        <parent link="base_link" />
        <child link="rb_wheel" />
        <origin xyz="-0.45 -0.6 -0.6" rpy="${pi/2} 0 0"/>
        <axis xyz="0 0 -1"/>
    </joint>

</robot>