<?xml version="1.0" encoding="UTF-8"?>
<robot xmlns:xacro="http://www.ros.org/wiki/xacro" name="robot">

    <xacro:include filename="$(find rover_desc)/urdf/inertial_macros.xacro"/>
    <xacro:include filename="$(find rover_desc)/urdf/gazebo_control.xacro"/>
    <!-- <xacro:include filename="$(find rover_desc)/urdf/sensors.xacro"/> -->

    <material name="white">
        <color rgba="1 1 1 1" />
    </material>

    <material name="orange">
        <color rgba="1 0.3 0.1 1"/>
    </material>

    <material name="blue">
        <color rgba="0.2 0.2 1 1"/>
    </material>

    <material name="black">
        <color rgba="0 0 0 1"/>
    </material>

    <!-- <link name="world" />

    <joint name="virtual_joint" type="fixed">
        <parent link="world"/>
        <child link="base_link"/>
        <origin xyz="0 0 0.825" rpy="0 0 0" />
    </joint> -->

    <link name="base_link">
        <visual>
            <origin xyz="0 0 0"/>
            <geometry>
                <box size="1.8 1.2 1.2"/>
            </geometry>
            <material name="white"/>
        </visual>
        <collision>
            <origin xyz="0 0 0"/>
            <geometry>
                <box size="1.8 1.2 1.2"/>
            </geometry>
        </collision>
        <xacro:inertial_box mass="5.0" x="1.8" y="1.2" z="1.2">
            <origin xyz="0 0 0" rpy="0 0 0"/>
        </xacro:inertial_box>
    </link>


    <!-- <joint name="base_link_joint" type="fixed">
        <parent link="base_link" />
        <child link="base_link"/>
        <origin xyz="0 0 0 "/>
    </joint> -->

    <!-- <link name="base_link">
        <visual>
            <origin xyz="0 0 0"/>
            <geometry>
                <box size="1.8 1.2 1.2"/>
            </geometry>
            <material name="white"/>
        </visual>
        <collision>
            <origin xyz="0 0 0"/>
            <geometry>
                <box size="1.8 1.2 1.2"/>
            </geometry>
        </collision>
        <xacro:inertial_box mass="5.0" x="1.8" y="1.2" z="1.2">
            <origin xyz="0 0 0" rpy="0 0 0"/>
        </xacro:inertial_box>
    </link> -->

    

    <link name="lf_wheel">
        <visual>
            <origin xyz="0 0 0"/>
            <geometry>
                <cylinder radius="0.225" length="0.22"/>
            </geometry>            
        </visual>
        <collision>
            <origin xyz="0 0 0"/>
            <geometry>
                <cylinder radius="0.225" length="0.22"/>
            </geometry>
        </collision>
        <xacro:inertial_cylinder mass="0.25" length="0.22" radius="0.225">
            <origin xyz="0 0 0" rpy="0 0 0"/>
        </xacro:inertial_cylinder>
    </link>

    <joint name="lf_wheel_joint" type="continuous">
        <parent link="base_link" />
        <child link="lf_wheel" />
        <origin xyz="0.45 0.6 -0.6" rpy="-${pi/2} 0 0"/>
        <axis xyz="0 0 1"/>
    </joint>

    <link name="rf_wheel">
        <visual>
            <origin xyz="0 0 0"/>
            <geometry>
                <cylinder radius="0.225" length="0.22"/>
            </geometry>            
        </visual>
        <collision>
            <origin xyz="0 0 0"/>
            <geometry>
                <cylinder radius="0.225" length="0.22"/>
            </geometry>
        </collision>
        <xacro:inertial_cylinder mass="0.25" length="0.22" radius="0.225">
            <origin xyz="0 0 0" rpy="0 0 0"/>
        </xacro:inertial_cylinder>
    </link>

    <joint name="rf_wheel_joint" type="continuous">
        <parent link="base_link" />
        <child link="rf_wheel" />
        <origin xyz="0.45 -0.6 -0.6" rpy="${pi/2} 0 0"/>
        <axis xyz="0 0 -1"/>
    </joint>

    <link name="lb_wheel">
        <visual>
            <origin xyz="0 0 0"/>
            <geometry>
                <cylinder radius="0.225" length="0.22"/>
            </geometry>            
        </visual>
        <collision>
            <origin xyz="0 0 0"/>
            <geometry>
                <cylinder radius="0.225" length="0.22"/>
            </geometry>
        </collision>
        <xacro:inertial_cylinder mass="0.25" length="0.22" radius="0.225">
            <origin xyz="0 0 0" rpy="0 0 0"/>
        </xacro:inertial_cylinder>
    </link>

    <joint name="lb_wheel_joint" type="continuous">
        <parent link="base_link" />
        <child link="lb_wheel" />
        <origin xyz="-0.45 0.6 -0.6" rpy="-${pi/2} 0 0"/>
        <axis xyz="0 0 1"/>
    </joint>

    <link name="rb_wheel">
        <visual>
            <origin xyz="0 0 0"/>
            <geometry>
                <cylinder radius="0.225" length="0.22"/>
            </geometry>            
        </visual>
        <collision>
            <origin xyz="0 0 0"/>
            <geometry>
                <cylinder radius="0.225" length="0.22"/>
            </geometry>
        </collision>
        <xacro:inertial_cylinder mass="0.25" length="0.22" radius="0.225">
            <origin xyz="0 0 0" rpy="0 0 0"/>
        </xacro:inertial_cylinder>
    </link>

    <joint name="rb_wheel_joint" type="continuous">
        <parent link="base_link" />
        <child link="rb_wheel" />
        <origin xyz="-0.45 -0.6 -0.6" rpy="${pi/2} 0 0"/>
        <axis xyz="0 0 -1"/>
    </joint>

</robot>